[2023-11-05T16:18:04.409+0000] {taskinstance.py:1090} INFO - Dependencies all met for dep_context=non-requeueable deps ti=<TaskInstance: ETL_People_Places.load_people manual__2023-11-05T16:17:59.442714+00:00 [queued]>
[2023-11-05T16:18:04.428+0000] {taskinstance.py:1090} INFO - Dependencies all met for dep_context=requeueable deps ti=<TaskInstance: ETL_People_Places.load_people manual__2023-11-05T16:17:59.442714+00:00 [queued]>
[2023-11-05T16:18:04.430+0000] {taskinstance.py:1288} INFO - 
--------------------------------------------------------------------------------
[2023-11-05T16:18:04.432+0000] {taskinstance.py:1289} INFO - Starting attempt 1 of 1
[2023-11-05T16:18:04.434+0000] {taskinstance.py:1290} INFO - 
--------------------------------------------------------------------------------
[2023-11-05T16:18:04.458+0000] {taskinstance.py:1309} INFO - Executing <Task(DockerOperator): load_people> on 2023-11-05 16:17:59.442714+00:00
[2023-11-05T16:18:04.465+0000] {standard_task_runner.py:55} INFO - Started process 637 to run task
[2023-11-05T16:18:04.470+0000] {standard_task_runner.py:82} INFO - Running: ['***', 'tasks', 'run', 'ETL_People_Places', 'load_people', 'manual__2023-11-05T16:17:59.442714+00:00', '--job-id', '9', '--raw', '--subdir', 'DAGS_FOLDER/ETL_people_places_dag.py', '--cfg-path', '/tmp/tmp8jtu7vql']
[2023-11-05T16:18:04.473+0000] {standard_task_runner.py:83} INFO - Job 9: Subtask load_people
[2023-11-05T16:18:04.575+0000] {task_command.py:389} INFO - Running <TaskInstance: ETL_People_Places.load_people manual__2023-11-05T16:17:59.442714+00:00 [running]> on host 6e77a7a050e2
[2023-11-05T16:18:04.692+0000] {taskinstance.py:1518} INFO - Exporting the following env vars:
AIRFLOW_CTX_DAG_EMAIL=***@example.com
AIRFLOW_CTX_DAG_OWNER=***
AIRFLOW_CTX_DAG_ID=ETL_People_Places
AIRFLOW_CTX_TASK_ID=load_people
AIRFLOW_CTX_EXECUTION_DATE=2023-11-05T16:17:59.442714+00:00
AIRFLOW_CTX_TRY_NUMBER=1
AIRFLOW_CTX_DAG_RUN_ID=manual__2023-11-05T16:17:59.442714+00:00
[2023-11-05T16:18:04.727+0000] {docker.py:306} INFO - Starting docker container from image load_people:latest
[2023-11-05T16:18:04.742+0000] {taskinstance.py:1776} ERROR - Task failed with exception
Traceback (most recent call last):
  File "/home/airflow/.local/lib/python3.7/site-packages/docker/api/client.py", line 268, in _raise_for_status
    response.raise_for_status()
  File "/home/airflow/.local/lib/python3.7/site-packages/requests/models.py", line 1021, in raise_for_status
    raise HTTPError(http_error_msg, response=self)
requests.exceptions.HTTPError: 400 Client Error: Bad Request for url: http://docker-socket-proxy:2375/v1.43/containers/create

The above exception was the direct cause of the following exception:

Traceback (most recent call last):
  File "/home/airflow/.local/lib/python3.7/site-packages/airflow/providers/docker/operators/docker.py", line 448, in execute
    return self._run_image()
  File "/home/airflow/.local/lib/python3.7/site-packages/airflow/providers/docker/operators/docker.py", line 323, in _run_image
    return self._run_image_with_mounts(self.mounts, add_tmp_variable=False)
  File "/home/airflow/.local/lib/python3.7/site-packages/airflow/providers/docker/operators/docker.py", line 363, in _run_image_with_mounts
    hostname=self.hostname,
  File "/home/airflow/.local/lib/python3.7/site-packages/docker/api/container.py", line 431, in create_container
    return self.create_container_from_config(config, name, platform)
  File "/home/airflow/.local/lib/python3.7/site-packages/docker/api/container.py", line 448, in create_container_from_config
    return self._result(res, True)
  File "/home/airflow/.local/lib/python3.7/site-packages/docker/api/client.py", line 274, in _result
    self._raise_for_status(response)
  File "/home/airflow/.local/lib/python3.7/site-packages/docker/api/client.py", line 270, in _raise_for_status
    raise create_api_error_from_http_exception(e) from e
  File "/home/airflow/.local/lib/python3.7/site-packages/docker/errors.py", line 39, in create_api_error_from_http_exception
    raise cls(e, response=response, explanation=explanation) from e
docker.errors.APIError: 400 Client Error for http://docker-socket-proxy:2375/v1.43/containers/create: Bad Request ("invalid mount config for type "bind": field Source must not be empty")
[2023-11-05T16:18:04.759+0000] {taskinstance.py:1332} INFO - Marking task as FAILED. dag_id=ETL_People_Places, task_id=load_people, execution_date=20231105T161759, start_date=20231105T161804, end_date=20231105T161804
[2023-11-05T16:18:04.775+0000] {standard_task_runner.py:105} ERROR - Failed to execute job 9 for task load_people (400 Client Error for http://docker-socket-proxy:2375/v1.43/containers/create: Bad Request ("invalid mount config for type "bind": field Source must not be empty"); 637)
[2023-11-05T16:18:04.804+0000] {local_task_job.py:212} INFO - Task exited with return code 1
[2023-11-05T16:18:04.843+0000] {taskinstance.py:2596} INFO - 0 downstream tasks scheduled from follow-on schedule check
