[2023-11-05T16:51:41.083+0000] {taskinstance.py:1090} INFO - Dependencies all met for dep_context=non-requeueable deps ti=<TaskInstance: ETL_People_Places.load_people manual__2023-11-05T16:51:32.247848+00:00 [queued]>
[2023-11-05T16:51:41.095+0000] {taskinstance.py:1090} INFO - Dependencies all met for dep_context=requeueable deps ti=<TaskInstance: ETL_People_Places.load_people manual__2023-11-05T16:51:32.247848+00:00 [queued]>
[2023-11-05T16:51:41.097+0000] {taskinstance.py:1288} INFO - 
--------------------------------------------------------------------------------
[2023-11-05T16:51:41.098+0000] {taskinstance.py:1289} INFO - Starting attempt 1 of 1
[2023-11-05T16:51:41.099+0000] {taskinstance.py:1290} INFO - 
--------------------------------------------------------------------------------
[2023-11-05T16:51:41.117+0000] {taskinstance.py:1309} INFO - Executing <Task(DockerOperator): load_people> on 2023-11-05 16:51:32.247848+00:00
[2023-11-05T16:51:41.123+0000] {standard_task_runner.py:55} INFO - Started process 3465 to run task
[2023-11-05T16:51:41.126+0000] {standard_task_runner.py:82} INFO - Running: ['***', 'tasks', 'run', 'ETL_People_Places', 'load_people', 'manual__2023-11-05T16:51:32.247848+00:00', '--job-id', '36', '--raw', '--subdir', 'DAGS_FOLDER/ETL_people_places_dag.py', '--cfg-path', '/tmp/tmpbor40bu5']
[2023-11-05T16:51:41.130+0000] {standard_task_runner.py:83} INFO - Job 36: Subtask load_people
[2023-11-05T16:51:41.228+0000] {task_command.py:389} INFO - Running <TaskInstance: ETL_People_Places.load_people manual__2023-11-05T16:51:32.247848+00:00 [running]> on host 526ca62ab683
[2023-11-05T16:51:41.314+0000] {taskinstance.py:1518} INFO - Exporting the following env vars:
AIRFLOW_CTX_DAG_EMAIL=***@example.com
AIRFLOW_CTX_DAG_OWNER=***
AIRFLOW_CTX_DAG_ID=ETL_People_Places
AIRFLOW_CTX_TASK_ID=load_people
AIRFLOW_CTX_EXECUTION_DATE=2023-11-05T16:51:32.247848+00:00
AIRFLOW_CTX_TRY_NUMBER=1
AIRFLOW_CTX_DAG_RUN_ID=manual__2023-11-05T16:51:32.247848+00:00
[2023-11-05T16:51:41.344+0000] {docker.py:306} INFO - Starting docker container from image load_people:latest
[2023-11-05T16:51:41.749+0000] {docker.py:373} INFO - Traceback (most recent call last):
  File "//main.py", line 22, in <module>
[2023-11-05T16:51:41.751+0000] {docker.py:373} INFO - with open('data/places.csv', 'r') as file:
FileNotFoundError: [Errno 2] No such file or directory: 'data/places.csv'
[2023-11-05T16:51:41.906+0000] {taskinstance.py:1776} ERROR - Task failed with exception
Traceback (most recent call last):
  File "/home/airflow/.local/lib/python3.7/site-packages/airflow/providers/docker/operators/docker.py", line 448, in execute
    return self._run_image()
  File "/home/airflow/.local/lib/python3.7/site-packages/airflow/providers/docker/operators/docker.py", line 323, in _run_image
    return self._run_image_with_mounts(self.mounts, add_tmp_variable=False)
  File "/home/airflow/.local/lib/python3.7/site-packages/airflow/providers/docker/operators/docker.py", line 382, in _run_image_with_mounts
    raise AirflowException(f"Docker container failed: {repr(result)} lines {joined_log_lines}")
airflow.exceptions.AirflowException: Docker container failed: {'StatusCode': 1} lines Traceback (most recent call last):
  File "//main.py", line 22, in <module>
with open('data/places.csv', 'r') as file:
FileNotFoundError: [Errno 2] No such file or directory: 'data/places.csv'
[2023-11-05T16:51:41.918+0000] {taskinstance.py:1332} INFO - Marking task as FAILED. dag_id=ETL_People_Places, task_id=load_people, execution_date=20231105T165132, start_date=20231105T165141, end_date=20231105T165141
[2023-11-05T16:51:41.947+0000] {standard_task_runner.py:105} ERROR - Failed to execute job 36 for task load_people (Docker container failed: {'StatusCode': 1} lines Traceback (most recent call last):
  File "//main.py", line 22, in <module>
with open('data/places.csv', 'r') as file:
FileNotFoundError: [Errno 2] No such file or directory: 'data/places.csv'; 3465)
[2023-11-05T16:51:41.985+0000] {local_task_job.py:212} INFO - Task exited with return code 1
[2023-11-05T16:51:42.026+0000] {taskinstance.py:2596} INFO - 0 downstream tasks scheduled from follow-on schedule check
