[2023-11-05T16:28:09.797+0000] {taskinstance.py:1090} INFO - Dependencies all met for dep_context=non-requeueable deps ti=<TaskInstance: ETL_People_Places.load_people manual__2023-11-05T16:28:01.403689+00:00 [queued]>
[2023-11-05T16:28:09.811+0000] {taskinstance.py:1090} INFO - Dependencies all met for dep_context=requeueable deps ti=<TaskInstance: ETL_People_Places.load_people manual__2023-11-05T16:28:01.403689+00:00 [queued]>
[2023-11-05T16:28:09.812+0000] {taskinstance.py:1288} INFO - 
--------------------------------------------------------------------------------
[2023-11-05T16:28:09.814+0000] {taskinstance.py:1289} INFO - Starting attempt 1 of 1
[2023-11-05T16:28:09.816+0000] {taskinstance.py:1290} INFO - 
--------------------------------------------------------------------------------
[2023-11-05T16:28:09.847+0000] {taskinstance.py:1309} INFO - Executing <Task(DockerOperator): load_people> on 2023-11-05 16:28:01.403689+00:00
[2023-11-05T16:28:09.854+0000] {standard_task_runner.py:55} INFO - Started process 965 to run task
[2023-11-05T16:28:09.858+0000] {standard_task_runner.py:82} INFO - Running: ['***', 'tasks', 'run', 'ETL_People_Places', 'load_people', 'manual__2023-11-05T16:28:01.403689+00:00', '--job-id', '24', '--raw', '--subdir', 'DAGS_FOLDER/ETL_people_places_dag.py', '--cfg-path', '/tmp/tmpm8kuv0fr']
[2023-11-05T16:28:09.862+0000] {standard_task_runner.py:83} INFO - Job 24: Subtask load_people
[2023-11-05T16:28:09.969+0000] {task_command.py:389} INFO - Running <TaskInstance: ETL_People_Places.load_people manual__2023-11-05T16:28:01.403689+00:00 [running]> on host 526ca62ab683
[2023-11-05T16:28:10.080+0000] {taskinstance.py:1518} INFO - Exporting the following env vars:
AIRFLOW_CTX_DAG_EMAIL=***@example.com
AIRFLOW_CTX_DAG_OWNER=***
AIRFLOW_CTX_DAG_ID=ETL_People_Places
AIRFLOW_CTX_TASK_ID=load_people
AIRFLOW_CTX_EXECUTION_DATE=2023-11-05T16:28:01.403689+00:00
AIRFLOW_CTX_TRY_NUMBER=1
AIRFLOW_CTX_DAG_RUN_ID=manual__2023-11-05T16:28:01.403689+00:00
[2023-11-05T16:28:10.108+0000] {docker.py:306} INFO - Starting docker container from image load_people:latest
[2023-11-05T16:28:10.743+0000] {docker.py:373} INFO - Traceback (most recent call last):
  File "//main.py", line 22, in <module>
[2023-11-05T16:28:10.746+0000] {docker.py:373} INFO - with open('data/places.csv', 'r') as file:
FileNotFoundError: [Errno 2] No such file or directory: 'data/places.csv'
[2023-11-05T16:28:10.922+0000] {taskinstance.py:1776} ERROR - Task failed with exception
Traceback (most recent call last):
  File "/home/airflow/.local/lib/python3.7/site-packages/airflow/providers/docker/operators/docker.py", line 448, in execute
    return self._run_image()
  File "/home/airflow/.local/lib/python3.7/site-packages/airflow/providers/docker/operators/docker.py", line 323, in _run_image
    return self._run_image_with_mounts(self.mounts, add_tmp_variable=False)
  File "/home/airflow/.local/lib/python3.7/site-packages/airflow/providers/docker/operators/docker.py", line 382, in _run_image_with_mounts
    raise AirflowException(f"Docker container failed: {repr(result)} lines {joined_log_lines}")
airflow.exceptions.AirflowException: Docker container failed: {'StatusCode': 1} lines Traceback (most recent call last):
  File "//main.py", line 22, in <module>
with open('data/places.csv', 'r') as file:
FileNotFoundError: [Errno 2] No such file or directory: 'data/places.csv'
[2023-11-05T16:28:10.929+0000] {taskinstance.py:1332} INFO - Marking task as FAILED. dag_id=ETL_People_Places, task_id=load_people, execution_date=20231105T162801, start_date=20231105T162809, end_date=20231105T162810
[2023-11-05T16:28:10.950+0000] {standard_task_runner.py:105} ERROR - Failed to execute job 24 for task load_people (Docker container failed: {'StatusCode': 1} lines Traceback (most recent call last):
  File "//main.py", line 22, in <module>
with open('data/places.csv', 'r') as file:
FileNotFoundError: [Errno 2] No such file or directory: 'data/places.csv'; 965)
[2023-11-05T16:28:10.975+0000] {local_task_job.py:212} INFO - Task exited with return code 1
[2023-11-05T16:28:11.024+0000] {taskinstance.py:2596} INFO - 0 downstream tasks scheduled from follow-on schedule check
