[2023-11-05T16:09:45.317+0000] {taskinstance.py:1090} INFO - Dependencies all met for dep_context=non-requeueable deps ti=<TaskInstance: ETL_People_Places.load_places manual__2023-11-05T16:09:43.864071+00:00 [queued]>
[2023-11-05T16:09:45.356+0000] {taskinstance.py:1090} INFO - Dependencies all met for dep_context=requeueable deps ti=<TaskInstance: ETL_People_Places.load_places manual__2023-11-05T16:09:43.864071+00:00 [queued]>
[2023-11-05T16:09:45.359+0000] {taskinstance.py:1288} INFO - 
--------------------------------------------------------------------------------
[2023-11-05T16:09:45.364+0000] {taskinstance.py:1289} INFO - Starting attempt 1 of 1
[2023-11-05T16:09:45.368+0000] {taskinstance.py:1290} INFO - 
--------------------------------------------------------------------------------
[2023-11-05T16:09:45.418+0000] {taskinstance.py:1309} INFO - Executing <Task(DockerOperator): load_places> on 2023-11-05 16:09:43.864071+00:00
[2023-11-05T16:09:45.435+0000] {standard_task_runner.py:55} INFO - Started process 825 to run task
[2023-11-05T16:09:45.445+0000] {standard_task_runner.py:82} INFO - Running: ['***', 'tasks', 'run', 'ETL_People_Places', 'load_places', 'manual__2023-11-05T16:09:43.864071+00:00', '--job-id', '3', '--raw', '--subdir', 'DAGS_FOLDER/ETL_people_places_dag.py', '--cfg-path', '/tmp/tmpw_8i3z49']
[2023-11-05T16:09:45.455+0000] {standard_task_runner.py:83} INFO - Job 3: Subtask load_places
[2023-11-05T16:09:45.644+0000] {task_command.py:389} INFO - Running <TaskInstance: ETL_People_Places.load_places manual__2023-11-05T16:09:43.864071+00:00 [running]> on host b04fb40e04d9
[2023-11-05T16:09:45.848+0000] {taskinstance.py:1518} INFO - Exporting the following env vars:
AIRFLOW_CTX_DAG_EMAIL=***@example.com
AIRFLOW_CTX_DAG_OWNER=***
AIRFLOW_CTX_DAG_ID=ETL_People_Places
AIRFLOW_CTX_TASK_ID=load_places
AIRFLOW_CTX_EXECUTION_DATE=2023-11-05T16:09:43.864071+00:00
AIRFLOW_CTX_TRY_NUMBER=1
AIRFLOW_CTX_DAG_RUN_ID=manual__2023-11-05T16:09:43.864071+00:00
[2023-11-05T16:09:45.943+0000] {docker.py:306} INFO - Starting docker container from image load_places:latest
[2023-11-05T16:09:47.176+0000] {docker.py:373} INFO - Traceback (most recent call last):
  File "//main.py", line 31, in <module>
[2023-11-05T16:09:47.179+0000] {docker.py:373} INFO - with open('data/people.csv', 'r') as file:
FileNotFoundError: [Errno 2] No such file or directory: 'data/people.csv'
[2023-11-05T16:09:47.484+0000] {taskinstance.py:1776} ERROR - Task failed with exception
Traceback (most recent call last):
  File "/home/airflow/.local/lib/python3.7/site-packages/airflow/providers/docker/operators/docker.py", line 448, in execute
    return self._run_image()
  File "/home/airflow/.local/lib/python3.7/site-packages/airflow/providers/docker/operators/docker.py", line 323, in _run_image
    return self._run_image_with_mounts(self.mounts, add_tmp_variable=False)
  File "/home/airflow/.local/lib/python3.7/site-packages/airflow/providers/docker/operators/docker.py", line 382, in _run_image_with_mounts
    raise AirflowException(f"Docker container failed: {repr(result)} lines {joined_log_lines}")
airflow.exceptions.AirflowException: Docker container failed: {'StatusCode': 1} lines Traceback (most recent call last):
  File "//main.py", line 31, in <module>
with open('data/people.csv', 'r') as file:
FileNotFoundError: [Errno 2] No such file or directory: 'data/people.csv'
[2023-11-05T16:09:47.500+0000] {taskinstance.py:1332} INFO - Marking task as FAILED. dag_id=ETL_People_Places, task_id=load_places, execution_date=20231105T160943, start_date=20231105T160945, end_date=20231105T160947
[2023-11-05T16:09:47.542+0000] {standard_task_runner.py:105} ERROR - Failed to execute job 3 for task load_places (Docker container failed: {'StatusCode': 1} lines Traceback (most recent call last):
  File "//main.py", line 31, in <module>
with open('data/people.csv', 'r') as file:
FileNotFoundError: [Errno 2] No such file or directory: 'data/people.csv'; 825)
[2023-11-05T16:09:47.570+0000] {local_task_job.py:212} INFO - Task exited with return code 1
[2023-11-05T16:09:47.661+0000] {taskinstance.py:2596} INFO - 0 downstream tasks scheduled from follow-on schedule check
